Workbook

Sheet Summary
A1: Place-based data inventory · refined set · summary
A2: Counts are live formulas over the Verification tab (every kept dataset), except the funnel (fixed counts; sources named).
A4: Tier × theme | B4: Gold | C4: Silver | D4: Bronze | E4: Browser needed | F4: Failed | G4: Total
B5: =COUNTIFS(Verification!$D$2:$D$667,$A5,Verification!$B$2:$B$667,"Gold") | C5: =COUNTIFS(Verification!$D$2:$D$667,$A5,Verification!$B$2:$B$667,"Silver") | D5: =COUNTIFS(Verification!$D$2:$D$667,$A5,Verification!$B$2:$B$667,"Bronze") | E5: =COUNTIFS(Verification!$D$2:$D$667,$A5,Verification!$B$2:$B$667,"Browser needed") | F5: =COUNTIFS(Verification!$D$2:$D$667,$A5,Verification!$B$2:$B$667,"Failed") | G5: =SUM(B5:F5)
A6: air quality | B6: =COUNTIFS(Verification!$D$2:$D$667,$A6,Verification!$B$2:$B$667,"Gold") | C6: =COUNTIFS(Verification!$D$2:$D$667,$A6,Verification!$B$2:$B$667,"Silver") | D6: =COUNTIFS(Verification!$D$2:$D$667,$A6,Verification!$B$2:$B$667,"Bronze") | E6: =COUNTIFS(Verification!$D$2:$D$667,$A6,Verification!$B$2:$B$667,"Browser needed") | F6: =COUNTIFS(Verification!$D$2:$D$667,$A6,Verification!$B$2:$B$667,"Failed") | G6: =SUM(B6:F6)
A7: boundaries | B7: =COUNTIFS(Verification!$D$2:$D$667,$A7,Verification!$B$2:$B$667,"Gold") | C7: =COUNTIFS(Verification!$D$2:$D$667,$A7,Verification!$B$2:$B$667,"Silver") | D7: =COUNTIFS(Verification!$D$2:$D$667,$A7,Verification!$B$2:$B$667,"Bronze") | E7: =COUNTIFS(Verification!$D$2:$D$667,$A7,Verification!$B$2:$B$667,"Browser needed") | F7: =COUNTIFS(Verification!$D$2:$D$667,$A7,Verification!$B$2:$B$667,"Failed") | G7: =SUM(B7:F7)
A8: built_environment | B8: =COUNTIFS(Verification!$D$2:$D$667,$A8,Verification!$B$2:$B$667,"Gold") | C8: =COUNTIFS(Verification!$D$2:$D$667,$A8,Verification!$B$2:$B$667,"Silver") | D8: =COUNTIFS(Verification!$D$2:$D$667,$A8,Verification!$B$2:$B$667,"Bronze") | E8: =COUNTIFS(Verification!$D$2:$D$667,$A8,Verification!$B$2:$B$667,"Browser needed") | F8: =COUNTIFS(Verification!$D$2:$D$667,$A8,Verification!$B$2:$B$667,"Failed") | G8: =SUM(B8:F8)
A9: climate_hazard | B9: =COUNTIFS(Verification!$D$2:$D$667,$A9,Verification!$B$2:$B$667,"Gold") | C9: =COUNTIFS(Verification!$D$2:$D$667,$A9,Verification!$B$2:$B$667,"Silver") | D9: =COUNTIFS(Verification!$D$2:$D$667,$A9,Verification!$B$2:$B$667,"Bronze") | E9: =COUNTIFS(Verification!$D$2:$D$667,$A9,Verification!$B$2:$B$667,"Browser needed") | F9: =COUNTIFS(Verification!$D$2:$D$667,$A9,Verification!$B$2:$B$667,"Failed") | G9: =SUM(B9:F9)
A10: demographics | B10: =COUNTIFS(Verification!$D$2:$D$667,$A10,Verification!$B$2:$B$667,"Gold") | C10: =COUNTIFS(Verification!$D$2:$D$667,$A10,Verification!$B$2:$B$667,"Silver") | D10: =COUNTIFS(Verification!$D$2:$D$667,$A10,Verification!$B$2:$B$667,"Bronze") | E10: =COUNTIFS(Verification!$D$2:$D$667,$A10,Verification!$B$2:$B$667,"Browser needed") | F10: =COUNTIFS(Verification!$D$2:$D$667,$A10,Verification!$B$2:$B$667,"Failed") | G10: =SUM(B10:F10)
A11: environment | B11: =COUNTIFS(Verification!$D$2:$D$667,$A11,Verification!$B$2:$B$667,"Gold") | C11: =COUNTIFS(Verification!$D$2:$D$667,$A11,Verification!$B$2:$B$667,"Silver") | D11: =COUNTIFS(Verification!$D$2:$D$667,$A11,Verification!$B$2:$B$667,"Bronze") | E11: =COUNTIFS(Verification!$D$2:$D$667,$A11,Verification!$B$2:$B$667,"Browser needed") | F11: =COUNTIFS(Verification!$D$2:$D$667,$A11,Verification!$B$2:$B$667,"Failed") | G11: =SUM(B11:F11)
A12: food_access | B12: =COUNTIFS(Verification!$D$2:$D$667,$A12,Verification!$B$2:$B$667,"Gold") | C12: =COUNTIFS(Verification!$D$2:$D$667,$A12,Verification!$B$2:$B$667,"Silver") | D12: =COUNTIFS(Verification!$D$2:$D$667,$A12,Verification!$B$2:$B$667,"Bronze") | E12: =COUNTIFS(Verification!$D$2:$D$667,$A12,Verification!$B$2:$B$667,"Browser needed") | F12: =COUNTIFS(Verification!$D$2:$D$667,$A12,Verification!$B$2:$B$667,"Failed") | G12: =SUM(B12:F12)
A13: health surveys | B13: =COUNTIFS(Verification!$D$2:$D$667,$A13,Verification!$B$2:$B$667,"Gold") | C13: =COUNTIFS(Verification!$D$2:$D$667,$A13,Verification!$B$2:$B$667,"Silver") | D13: =COUNTIFS(Verification!$D$2:$D$667,$A13,Verification!$B$2:$B$667,"Bronze") | E13: =COUNTIFS(Verification!$D$2:$D$667,$A13,Verification!$B$2:$B$667,"Browser needed") | F13: =COUNTIFS(Verification!$D$2:$D$667,$A13,Verification!$B$2:$B$667,"Failed") | G13: =SUM(B13:F13)
A14: health_outcome | B14: =COUNTIFS(Verification!$D$2:$D$667,$A14,Verification!$B$2:$B$667,"Gold") | C14: =COUNTIFS(Verification!$D$2:$D$667,$A14,Verification!$B$2:$B$667,"Silver") | D14: =COUNTIFS(Verification!$D$2:$D$667,$A14,Verification!$B$2:$B$667,"Bronze") | E14: =COUNTIFS(Verification!$D$2:$D$667,$A14,Verification!$B$2:$B$667,"Browser needed") | F14: =COUNTIFS(Verification!$D$2:$D$667,$A14,Verification!$B$2:$B$667,"Failed") | G14: =SUM(B14:F14)
A15: other | B15: =COUNTIFS(Verification!$D$2:$D$667,$A15,Verification!$B$2:$B$667,"Gold") | C15: =COUNTIFS(Verification!$D$2:$D$667,$A15,Verification!$B$2:$B$667,"Silver") | D15: =COUNTIFS(Verification!$D$2:$D$667,$A15,Verification!$B$2:$B$667,"Bronze") | E15: =COUNTIFS(Verification!$D$2:$D$667,$A15,Verification!$B$2:$B$667,"Browser needed") | F15: =COUNTIFS(Verification!$D$2:$D$667,$A15,Verification!$B$2:$B$667,"Failed") | G15: =SUM(B15:F15)
A16: sdoh | B16: =COUNTIFS(Verification!$D$2:$D$667,$A16,Verification!$B$2:$B$667,"Gold") | C16: =COUNTIFS(Verification!$D$2:$D$667,$A16,Verification!$B$2:$B$667,"Silver") | D16: =COUNTIFS(Verification!$D$2:$D$667,$A16,Verification!$B$2:$B$667,"Bronze") | E16: =COUNTIFS(Verification!$D$2:$D$667,$A16,Verification!$B$2:$B$667,"Browser needed") | F16: =COUNTIFS(Verification!$D$2:$D$667,$A16,Verification!$B$2:$B$667,"Failed") | G16: =SUM(B16:F16)
A17: socioeconomic | B17: =COUNTIFS(Verification!$D$2:$D$667,$A17,Verification!$B$2:$B$667,"Gold") | C17: =COUNTIFS(Verification!$D$2:$D$667,$A17,Verification!$B$2:$B$667,"Silver") | D17: =COUNTIFS(Verification!$D$2:$D$667,$A17,Verification!$B$2:$B$667,"Bronze") | E17: =COUNTIFS(Verification!$D$2:$D$667,$A17,Verification!$B$2:$B$667,"Browser needed") | F17: =COUNTIFS(Verification!$D$2:$D$667,$A17,Verification!$B$2:$B$667,"Failed") | G17: =SUM(B17:F17)
... A20: water quality | B20: =COUNTIFS(Verification!$D$2:$D$667,$A20,Verification!$B$2:$B$667,"Gold") | C20: =COUNTIFS(Verification!$D$2:$D$667,$A20,Verification!$B$2:$B$667,"Silver") | D20: =COUNTIFS(Verification!$D$2:$D$667,$A20,Verification!$B$2:$B$667,"Bronze") | E20: =COUNTIFS(Verification!$D$2:$D$667,$A20,Verification!$B$2:$B$667,"Browser needed") | F20: =COUNTIFS(Verification!$D$2:$D$667,$A20,Verification!$B$2:$B$667,"Failed") | G20: =SUM(B20:F20)
A21: Total | B21: =SUM(B5:B20) | C21: =SUM(C5:C20) | D21: =SUM(D5:D20) | E21: =SUM(E5:E20) | F21: =SUM(F5:F20) | G21: =SUM(G5:G20)
A23: URL health | B23: Datasets
A24: healthy | B24: =COUNTIF(Verification!$E$2:$E$667,A24)
A25: degraded | B25: =COUNTIF(Verification!$E$2:$E$667,A25)
A26: moved | B26: =COUNTIF(Verification!$E$2:$E$667,A26)
A27: blocked | B27: =COUNTIF(Verification!$E$2:$E$667,A27)
A28: dead | B28: =COUNTIF(Verification!$E$2:$E$667,A28)
A29: n.a. | B29: =COUNTIF(Verification!$E$2:$E$667,A29)
A31: License class (content checks) | B31: Datasets
A32: open | B32: =COUNTIF(Verification!$F$2:$F$667,A32)
A33: attribution | B33: =COUNTIF(Verification!$F$2:$F$667,A33)
A34: non-commercial | B34: =COUNTIF(Verification!$F$2:$F$667,A34)
A35: registration | B35: =COUNTIF(Verification!$F$2:$F$667,A35)
A36: restricted | B36: =COUNTIF(Verification!$F$2:$F$667,A36)
A37: unknown | B37: =COUNTIF(Verification!$F$2:$F$667,A37)
A38: not checked | B38: =COUNTIF(Verification!$F$2:$F$667,A38)
A40: Finest unit | B40: Datasets
A41: point | B41: =COUNTIF(Verification!$G$2:$G$667,A41)
A42: unknown | B42: =COUNTIF(Verification!$G$2:$G$667,A42)
A43: tract | B43: =COUNTIF(Verification!$G$2:$G$667,A43)
A44: county | B44: =COUNTIF(Verification!$G$2:$G$667,A44)
A45: postcode_small_area | B45: =COUNTIF(Verification!$G$2:$G$667,A45)
A46: country | B46: =COUNTIF(Verification!$G$2:$G$667,A46)
...

Sheet About
A1: Place-based data inventory: refined set
A2: Date | B2: 29 October 2026 · OHDSI GIS Working Group · built 20–29 October 2026 (round 1 closed 28 October; on 29 October: working-group requests, the US federal licence rule, geometry classification, and file verification of the request datasets)
A3: What this is | B3: 666 public, place-based datasets that could be linked to where patients live (571 from round 1, then added on 29 October for working-group requests, file verification, category backfill and the priority-sources spike), each with a verification tier; the Round 2 pilot sheet holds 24 more. 345 are verified (Gold or Silver): years, spatial unit and access were read from the publisher's page, with the page URL kept as evidence. 15 are file-verified: a real file was downloaded and its columns, place key, geometry and years read (column verification_level). For US federal datasets the licence pass comes from the working group's rule (US federal works are public domain under 17 U.S.C. 105 unless a page says otherwise); their license_class is public_domain_us_federal.
A4: How it was built | B4: 1 Harvest: AI-assisted web sweeps plus scripted catalog-API listings (data.gov, HDX, Earthdata CMR, EU and national portals): 3,337 listings. 2 De-duplication: 3,160. 3 Split: 594 curated rows kept apart from 2,576 catalog leads; leads whose title names a spatial unit were added: 1,018. 4 Score: health relevance (0–3) and Gaia fit (joins today / needs a count or distance step / needs raster support / not linkable) from each listing. 5 Trim: 570 kept (relevant, data from 2000 on, not a one-off event, not hyper-local, not a portal). 6 URL health (21–22 Oct): scripted checks of every landing and access URL. 7 Content checks (22 and 28 Oct): an agent read the landing page and one documentation page of each live dataset (shortlist and step-3 groups on 22 Oct; the remaining live rows on 28 Oct). 8 Mirrors: four community mirrors or successors of withdrawn federal tools were added. 9 Duplicates (28 Oct): every flagged group among the kept rows was decided (see the Duplicates resolved tab).
A5: What 'verified' means | B5: Each check is pass / warn / fail / n.a. / not checked, with a detail and (for content checks) an evidence URL. Link checks: link live (2xx), redirect (same domain), TLS, soft-404 (page names the dataset), withdrawn (no retirement notice), access URL, format match, machine-readable metadata, persistent id, Wayback snapshot. Content checks: licence (+ class: open / attribution / non-commercial / registration / restricted), years (+ latest year), recency (pass 2020+, warn 2000–2019, fail before 2000 or discontinued), update cadence, version, finest unit, coverage, access route, join key, Gaia-loadable format. Workspace checks: in gaiaCatalog, recipe health from the deployment logs.
A6: Tiers | B6: Gold: link, page, withdrawn, licence, unit, years and access all pass; recency pass or warn. Silver: link passes and no fail among licence, unit, years, recency. Bronze: link live but content not read or incomplete. Browser needed: the site blocks scripts or has a certificate problem; it needs a real browser (a person or a browser agent). Failed: link dead, page generic, publisher says withdrawn, or data before 2000.
A7: Score | B7: 0–100, weighted: link 20, soft-404 10, withdrawn 10, licence 15, unit 15, years 7.5, recency 7.5, access 10, join key 10, machine metadata 5; pass = 1, warn = 0.5, fail = 0; normalised over the checks that apply.
A8: Assumptions | B8: Links were checked automatically on 21–22 October 2026; pages were read on 22 and 28 October, the working-group targets on 29 October, and the request datasets' files opened on 29 October (no other downloads). A 'fail' on licence means no licence statement was found on the pages read, not that the data are restricted; US federal rows pass by rule. A row keyed to one specific geometry dataset that is not yet found is capped at Silver. Relevance and Gaia-fit are rule-based from each listing; geometry classes are partly inferred (column geo_class_basis). Recency cut-off is 2000. Sites that block scripts were not worked around.
A9: Tabs | B9: Summary (live formulas over the Verification tab, plus the coverage of the assessment) · Refined set (Gold and Silver) · Verification (every kept row, colour-coded checks) · Browser queue · Duplicates resolved · Trimmed (what was left out and why) · Round 2 pilot (24 new health-facility registries, link-checked only).
A10: Files | B10: In docs/discovery of the Gaia workspace: inventory-combined-2026-10-29-fv.csv (every column; 604 rows incl. the round 2 pilot), inventory.csv (the Gold and Silver), landscape/landscape-report-2026-10-29.md, fileverify/fileverify-report-2026-10-29.md, exploration-1.5-report-2026-10-29.md, iterations/README.md (how it was built), TODO.md (what's next).
A11: Round 2 pilot | B11: 24 new health-facility registries (sweep 1 of 5; the other sweeps were not run). They were link-checked (part A) but not read for content (part B), so none is above Bronze. They are NOT in the Summary counts above (571 round 1 rows); see the foot of the Summary and the Round 2 pilot sheet. One more candidate (HRSA health-center sites) was already in the inventory and stays a single round 1 row.

Sheet Verification
A1: Dataset | B1: Tier | C1: Score | D1: Theme | E1: URL health | F1: License class | G1: Finest unit | H1: Gaia fit | I1: Health relevance (0-3) | J1: In gaiaCatalog | K1: Source | L1: Latest year | M1: Public access | N1: Verified on | O1: ✓ link live | P1: ✓ redirect | Q1: ✓ tls | R1: ✓ soft404 | S1: ✓ withdrawn | T1: ✓ access url | U1: ✓ format match | V1: ✓ machine metadata | W1: ✓ persistent id | X1: ✓ archived | Y1: ✓ license | Z1: ✓ temporal | AA1: ✓ recency | AB1: ✓ cadence | AC1: ✓ version | AD1: ✓ unit | AE1: ✓ coverage | AF1: ✓ access | AG1: ✓ join key | AH1: ✓ format gaia | AI1: ✓ in gaia | AJ1: ✓ recipe health | AK1: Blockers | AL1: Landing page | AM1: id
A2: Cartografia digitalizada de secciones censales | B2: Gold | C2: 98 | D2: boundaries | E2: healthy | F2: open | G2: polygon (seccion censal; small statistical area) | H2: Joins today | I2: 1 | K2: Curated | L2: 2025 | M2: open | N2: 2026-10-28 | O2: pass | P2: pass | Q2: pass | R2: pass | S2: pass | T2: n.a. | U2: n.a. | V2: warn | W2: warn | X2: pass | Y2: pass | Z2: pass | AA2: pass | AB2: warn | AC2: pass | AD2: pass | AE2: pass | AF2: pass | AG2: pass | AH2: pass | AI2: n.a. | AJ2: n.a. | AK2: machine_metadata(warn);persistent_id(warn);cadence(warn) | AL2: https://www.ine.es/ss/Satellite?L=es_ES&c=Page&cid=1259952026632&p=1259952026632&pagename=ProductosYServicios%2FPYSLayout | AM2: es_ine_secciones_censales
A3: Demografiska statistikomraden (DeSO) | B3: Gold | C3: 98 | D3: boundaries | E3: healthy | F3: open | G3: polygon (DeSO small statistical area; county and municipality as attributes) | H3: Joins today | I3: 1 | K3: Curated | L3: 2025 | M3: open | N3: 2026-10-28 | O3: pass | P3: pass | Q3: pass | R3: pass | S3: pass | T3: pass | U3: pass | V3: warn | W3: warn | X3: pass | Y3: pass | Z3: pass | AA3: pass | AB3: warn | AC3: pass | AD3: pass | AE3: pass | AF3: pass | AG3: pass | AH3: pass | AI3: n.a. | AJ3: n.a. | AK3: machine_metadata(warn);persistent_id(warn);cadence(warn) | AL3: https://www.scb.se/en/services/open-data-api/open-geodata/open-data-for-deso--demographic-statistical-areas/ | AM3: se_scb_deso
A4: Global Administrative Unit Layers (GAUL) | B4: Gold | C4: 93 | D4: boundaries | E4: healthy | F4: open | G4: admin2 | H4: Joins today | I4: 1 | K4: Curated | L4: 2024 | M4: open | N4: 2026-10-28 | O4: pass | P4: pass | Q4: pass | R4: pass | S4: pass | T4: pass | U4: warn | V4: warn | W4: warn | X4: pass | Y4: pass | Z4: pass | AA4: pass | AB4: pass | AC4: pass | AD4: pass | AE4: pass | AF4: pass | AG4: warn | AH4: pass | AI4: n.a. | AJ4: n.a. | AK4: format_match(warn);machine_metadata(warn);persistent_id(warn);join_key(warn) | AL4: https://www.fao.org/hih-geospatial-platform/news/detail/now-available--the-global-administrative-unit-layers-(gaul)-dataset---2024-edition/en | AM4: global_fao_gaul
A5: Postal codes point dataset and postal code to NUTS correspondence (Tercet) | B5: Gold | C5: 98 | D5: boundaries | E5: degraded | F5: open | G5: point | H5: Needs a count/distance step | I5: 1 | K5: Curated | L5: 2024 | M5: open | N5: 2026-10-28 | O5: pass | P5: pass | Q5: pass | R5: pass | S5: pass | T5: fail | U5: n.a. | V5: warn | W5: warn | X5: pass | Y5: pass | Z5: pass | AA5: pass | AB5: warn | AC5: pass | AD5: pass | AE5: pass | AF5: pass | AG5: pass | AH5: pass | AI5: n.a. | AJ5: n.a. | AK5: access_url;machine_metadata(warn);persistent_id(warn);cadence(warn) | AL5: https://ec.europa.eu/eurostat/web/gisco/geodata/administrative-units/postal-codes | AM5: eu_eurostat_gisco_postal_codes
A6: National Walkability Index | B6: Gold | C6: 95 | D6: built_environment | E6: healthy | F6: open | G6: block_group | H6: Joins today | I6: 3 | K6: Curated | L6: 2021 | M6: open | N6: 2026-10-22 | O6: pass | P6: pass | Q6: pass | R6: pass | S6: pass | T6: pass | U6: pass | V6: pass | W6: warn | X6: pass | Y6: pass | Z6: pass | AA6: pass | AB6: not_checked | AC6: warn | AD6: pass | AE6: pass | AF6: pass | AG6: warn | AH6: warn | AI6: n.a. | AJ6: n.a. | AK6: persistent_id(warn);version(warn);join_key(warn);format_gaia(warn) | AL6: https://catalog.data.gov/dataset/walkability-index | AM6: us_epa_national_walkability_index
A7: European Settlement Map (ESM) 2015 R2019 (2 m / 10 m built-up) | B7: Gold | C7: 92 | D7: built_environment | E7: degraded | F7: attribution | G7: grid_2m | H7: Needs raster support | I7: 2 | K7: Curated | L7: 2015 | M7: open | N7: 2026-10-28 | O7: pass | P7: pass | Q7: pass | R7: pass | S7: pass | T7: fail | U7: n.a. | V7: fail | W7: pass | X7: pass | Y7: pass | Z7: pass | AA7: warn | AB7: not_checked | AC7: pass | AD7: pass | AE7: warn | AF7: pass | AG7: pass | AH7: not_checked | AI7: n.a. | AJ7: n.a. | AK7: access_url;machine_metadata;recency(warn);coverage(warn) | AL7: https://human-settlement.emergency.copernicus.eu/datasets.php | AM7: eu_jrc_european_settlement_map
A8: Florida Managed Areas (FLMA) / state and national parks (FNAI GIS data) | B8: Gold | C8: 95 | D8: built_environment | E8: degraded | F8: attribution | G8: polygon | H8: Joins today | I8: 2 | J8: fl_2026_flma;mdc_2026_flma | K8: Curated | L8: 2026 | M8: open | N8: 2026-10-22 | O8: pass | P8: pass | Q8: pass | R8: pass | S8: pass | T8: n.a. | U8: n.a. | V8: fail | W8: warn | X8: pass | Y8: pass | Z8: pass | AA8: pass | AB8: pass | AC8: pass | AD8: pass | AE8: pass | AF8: pass | AG8: pass | AH8: pass | AI8: pass | AJ8: not_checked | AK8: machine_metadata;persistent_id(warn) | AL8: https://www.fnai.org/publications/gis-data | AM8: us_fnai_florida_managed_areas
A9: GHSL GHS-BUILT-S built-up surface grid (R2023A); related GHS-BUILT-V volume, GHS-BUILT-H height, GHS-BUILT-C characteristics, GHS-AGE | B9: Gold | C9: 95 | D9: built_environment | E9: degraded | F9: open | G9: grid_10m | H9: Needs raster support | I9: 2 | K9: Curated | L9: 2030 | M9: open | N9: 2026-10-28 | O9: pass | P9: pass | Q9: pass | R9: pass | S9: pass | T9: pass | U9: warn | V9: fail | W9: pass | X9: pass | Y9: pass | Z9: pass | AA9: pass | AB9: warn | AC9: pass | AD9: pass | AE9: pass | AF9: pass | AG9: pass | AH9: not_checked | AI9: n.a. | AJ9: n.a. | AK9: machine_metadata;format_match(warn);cadence(warn) | AL9: https://human-settlement.emergency.copernicus.eu/datasets.php | AM9: global_jrc_ghsl_ghs_built_s
A10: GHSL GHS-DUC Degree of Urbanisation Classification of administrative units (GADM 4.1), R2023A; GHS-WUP-DUC R2025A | B10: Gold | C10: 91 | D10: built_environment | E10: degraded | F10: open | G10: GADM 4.1 administrative units, levels 0-5 (GHS-DUC); grid_1km (GHS-WUP-DUC) | H10: Needs raster support | I10: 2 | K10: Curated | L10: 2030 | M10: open | N10: 2026-10-28 | O10: pass | P10: pass | Q10: pass | R10: pass | S10: pass | T10: pass | U10: warn | V10: fail | W10: pass | X10: pass | Y10: pass | Z10: pass | AA10: pass | AB10: warn | AC10: pass | AD10: pass | AE10: pass | AF10: pass | AG10: warn | AH10: not_checked | AI10: n.a. | AJ10: n.a. | AK10: machine_metadata;format_match(warn);cadence(warn);join_key(warn) | AL10: https://human-settlement.emergency.copernicus.eu/datasets.php | AM10: global_jrc_ghsl_ghs_duc
A11: GHSL GHS-SMOD Degree of Urbanisation settlement model grid (R2023A) and GHS-WUP-DEGURBA (R2025A) | B11: Gold | C11: 95 | D11: built_environment | E11: degraded | F11: open | G11: grid_1km | H11: Needs raster support | I11: 2 | K11: Curated | L11: 2030 | M11: open | N11: 2026-10-28 | O11: pass | P11: pass | Q11: pass | R11: pass | S11: pass | T11: pass | U11: warn | V11: fail | W11: pass | X11: pass | Y11: pass | Z11: pass | AA11: pass | AB11: warn | AC11: pass | AD11: pass | AE11: pass | AF11: pass | AG11: pass | AH11: not_checked | AI11: n.a. | AJ11: n.a. | AK11: machine_metadata;format_match(warn);cadence(warn) | AL11: https://human-settlement.emergency.copernicus.eu/datasets.php | AM11: global_jrc_ghsl_ghs_smod
A12: Microsoft GlobalMLBuildingFootprints: worldwide building footprints derived from satellite imagery (with height estimates) | B12: Gold | C12: 98 | D12: built_environment | E12: degraded | F12: open | G12: polygon | H12: Joins today | I12: 2 | K12: Curated | L12: 2026 | M12: open | N12: 2026-10-22 | O12: pass | P12: pass | Q12: pass | R12: pass | S12: pass | T12: fail | U12: n.a. | V12: warn | W12: warn | X12: pass | Y12: pass | Z12: pass | AA12: pass | AB12: warn | AC12: warn | AD12: pass | AE12: pass | AF12: pass | AG12: pass | AH12: pass | AI12: n.a. | AJ12: n.a. | AK12: access_url;machine_metadata(warn);persistent_id(warn);cadence(warn);version(warn) | AL12: https://github.com/microsoft/GlobalMLBuildingFootprints | AM12: global_microsoft_building_footprints
A13: Open Buildings | B13: Gold | C13: 98 | D13: built_environment | E13: healthy | F13: open | G13: polygon (v3 footprints); grid_4m effective resolution, rasters provided at 50 cm (Temporal) | H13: Needs raster support | I13: 2 | K13: Curated | L13: 2023 | M13: open | N13: 2026-10-28 | O13: pass | P13: pass | Q13: pass | R13: pass | S13: pass | T13: pass | U13: warn | V13: warn | W13: warn | X13: pass | Y13: pass | Z13: pass | AA13: pass | AB13: warn | AC13: pass | AD13: pass | AE13: pass | AF13: pass | AG13: pass | AH13: pass | AI13: n.a. | AJ13: n.a. | AK13: format_match(warn);machine_metadata(warn);persistent_id(warn);cadence(warn) | AL13: https://sites.research.google/gr/open-buildings/ | AM13: global_google_open_buildings
A14: World Settlement Footprint (WSF) 2019; related WSF 2015, WSF Evolution (1985-2015), WSF 3D | B14: Gold | C14: 92 | D14: built_environment | E14: degraded | F14: open | G14: grid_10m | H14: Needs raster support | I14: 2 | K14: Curated | L14: 2019 | M14: open | N14: 2026-10-28 | O14: pass | P14: pass | Q14: pass | R14: pass | S14: pass | T14: fail | U14: n.a. | V14: fail | W14: pass | X14: pass | Y14: pass | Z14: pass | AA14: warn | AB14: not_checked | AC14: warn | AD14: pass | AE14: pass | AF14: pass | AG14: pass | AH14: pass | AI14: n.a. | AJ14: n.a. | AK14: access_url;machine_metadata;recency(warn);version(warn) | AL14: https://geoservice.dlr.de/web/datasets/wsf_2019 | AM14: global_dlr_wsf_2019
A15: gridMET (METDATA) | B15: Gold | C15: 98 | D15: climate_hazard | E15: healthy | F15: open | G15: grid_4km | H15: Needs raster support | I15: 3 | K15: Curated | L15: 2026 | M15: open | N15: 2026-10-22 | O15: pass | P15: pass | Q15: pass | R15: pass | S15: pass | T15: pass | U15: warn | V15: warn | W15: warn | X15: pass | Y15: pass | Z15: pass | AA15: pass | AB15: pass | AC15: warn | AD15: pass | AE15: pass | AF15: pass | AG15: pass | AH15: pass | AI15: n.a. | AJ15: n.a. | AK15: format_match(warn);machine_metadata(warn);persistent_id(warn);version(warn) | AL15: https://www.climatologylab.org/gridmet.html | AM15: us_climatologylab_gridmet
A16: Wildfire Risk to Communities | B16: Gold | C16: 93 | D16: climate_hazard | E16: healthy | F16: open | G16: grid_30m | H16: Needs raster support | I16: 2 | K16: Curated | L16: 2024 | M16: open | N16: 2026-10-28 | O16: pass | P16: pass | Q16: pass | R16: pass | S16: pass | T16: pass | U16: pass | V16: warn | W16: pass | X16: pass | Y16: pass | Z16: pass | AA16: pass | AB16: warn | AC16: pass | AD16: pass | AE16: pass | AF16: pass | AG16: warn | AH16: warn | AI16: n.a. | AJ16: n.a. | AK16: machine_metadata(warn);cadence(warn);join_key(warn);format_gaia(warn) | AL16: https://wildfirerisk.org/download/ | AM16: us_usfs_wildfire_risk_to_communities
A17: Zensus 2022 Gitterdaten (grid data 100 m / 1 km / 10 km) | B17: Gold | C17: 93 | D17: demographics | E17: healthy | F17: attribution | G17: grid_100m | H17: Needs raster support | I17: 3 | K17: Curated | L17: 2022 | M17: open | N17: 2026-10-22 | O17: pass | P17: pass | Q17: pass | R17: pass | S17: pass | T17: pass | U17: warn | V17: warn | W17: warn | X17: pass | Y17: pass | Z17: pass | AA17: pass | AB17: pass | AC17: not_checked | AD17: pass | AE17: pass | AF17: pass | AG17: warn | AH17: pass | AI17: n.a. | AJ17: n.a. | AK17: format_match(warn);machine_metadata(warn);persistent_id(warn);join_key(warn) | AL17: https://www.destatis.de/zensus2022 | AM17: de_destatis_zensus2022_grid
A18: American Community Survey 5-Year Data | B18: Gold | C18: 93 | D18: demographics | E18: healthy | F18: attribution | G18: block_group | H18: Joins today | I18: 2 | J18: fl_2021_acs_5yr_tract_fsr;mdc_2019_acs_5yr_tract_dvmt;mdc_2020_2024_acs_5yr_trends_tract_dvmt;mdc_2020_acs_5yr_tract_dvmt;mdc_2021_acs_5yr_tract_dvmt;mdc_2022_acs_5yr_tract_dvmt;mdc_2023_acs_5yr_tract_dvmt;mdc_2024_acs_5yr_tract_dvmt | K18: Curated | L18: 2024 | M18: unknown | N18: 2026-10-22 | O18: pass | P18: pass | Q18: pass | R18: pass | S18: pass | T18: pass | U18: pass | V18: warn | W18: warn | X18: pass | Y18: pass | Z18: pass | AA18: pass | AB18: pass | AC18: pass | AD18: pass | AE18: pass | AF18: pass | AG18: warn | AH18: warn | AI18: pass | AJ18: not_checked | AK18: machine_metadata(warn);persistent_id(warn);join_key(warn);format_gaia(warn) | AL18: https://www.census.gov/data/developers/data-sets/acs-5year.html | AM18: us_census_acs_5year
A19: Censo de Poblacion y Vivienda (Censo 2017; Censo 2024) | B19: Gold | C19: 98 | D19: demographics | E19: healthy | F19: open | G19: block (manzana) | H19: Joins today | I19: 2 | K19: Curated | L19: 2024 | M19: unknown | N19: 2026-10-22 | O19: pass | P19: pass | Q19: pass | R19: pass | S19: pass | T19: pass | U19: warn | V19: warn | W19: warn | X19: pass | Y19: pass | Z19: pass | AA19: pass | AB19: warn | AC19: pass | AD19: pass | AE19: warn | AF19: pass | AG19: not_checked | AH19: warn | AI19: n.a. | AJ19: n.a. | AK19: format_match(warn);machine_metadata(warn);persistent_id(warn);cadence(warn);coverage(warn);format_gaia(warn) | AL19: https://www.ine.gob.cl/estadisticas/sociales/censos-de-poblacion-y-vivienda/censo-de-poblacion-y-vivienda | AM19: cl_ine_censo
A20: Kaart van 100 meter bij 100 meter met statistieken | B20: Gold | C20: 98 | D20: demographics | E20: healthy | F20: attribution | G20: grid_100m | H20: Needs raster support | I20: 2 | K20: Curated | L20: 2025 | M20: open | N20: 2026-10-28 | O20: pass | P20: pass | Q20: pass | R20: pass | S20: pass | T20: n.a. | U20: n.a. | V20: warn | W20: warn | X20: pass | Y20: pass | Z20: pass | AA20: pass | AB20: pass | AC20: pass | AD20: pass | AE20: pass | AF20: pass | AG20: pass | AH20: pass | AI20: n.a. | AJ20: n.a. | AK20: machine_metadata(warn);persistent_id(warn) | AL20: https://www.cbs.nl/nl-nl/dossier/nederland-regionaal/geografische-data/kaart-van-100-meter-bij-100-meter-met-statistieken | AM20: nl_cbs_100m_grid
A21: Recensement de la population - Base infracommunale (IRIS) | B21: Gold | C21: 95 | D21: demographics | E21: degraded | F21: open | G21: IRIS (small statistical area, ~2000 inhabitants; commune level where commune not split into IRIS) | H21: Joins today | I21: 2 | K21: Curated | L21: 2023 | M21: open | N21: 2026-10-22 | O21: pass | P21: pass | Q21: pass | R21: pass | S21: pass | T21: warn | U21: n.a. | V21: fail | W21: warn | X21: pass | Y21: pass | Z21: pass | AA21: pass | AB21: not_checked | AC21: pass | AD21: pass | AE21: pass | AF21: pass | AG21: pass | AH21: pass | AI21: n.a. | AJ21: n.a. | AK21: machine_metadata;access_url(warn);persistent_id(warn) | AL21: https://www.insee.fr/fr/statistiques/9061333 | AM21: fr_insee_iris_rp
A22: 3D Hydrography Program (3DHP) hydrography data (successor to the NHD) | B22: Gold | C22: 98 | D22: environment | E22: healthy | F22: open | G22: line | H22: Needs a count/distance step | I22: 3 | K22: Mirror | L22: 2026 | M22: open | N22: 2026-10-28 | O22: pass | P22: pass | Q22: pass | R22: pass | S22: pass | T22: pass | U22: warn | V22: warn | W22: warn | X22: pass | Y22: pass | Z22: pass | AA22: pass | AB22: pass | AC22: warn | AD22: pass | AE22: pass | AF22: pass | AG22: pass | AH22: warn | AI22: n.a. | AJ22: n.a. | AK22: format_match(warn);machine_metadata(warn);persistent_id(warn);version(warn);format_gaia(warn) | AL22: https://www.usgs.gov/3d-hydrography-program | AM22: us_usgs_3dhp
A23: Air Quality e-Reporting (Air Quality download service) | B23: Gold | C23: 91 | D23: environment | E23: degraded | F23: attribution | G23: point | H23: Needs a count/distance step | I23: 3 | K23: Curated | L23: 2026 | M23: open | N23: 2026-10-22 | O23: pass | P23: pass | Q23: pass | R23: pass | S23: pass | T23: pass | U23: pass | V23: fail | W23: warn | X23: pass | Y23: pass | Z23: pass | AA23: pass | AB23: not_checked | AC23: warn | AD23: pass | AE23: warn | AF23: pass | AG23: warn | AH23: warn | AI23: n.a. | AJ23: n.a. | AK23: machine_metadata;persistent_id(warn);version(warn);coverage(warn);join_key(warn);format_gaia(warn) | AL23: https://www.eea.europa.eu/en/datahub/datahubitem-view/778ef9f5-6293-4846-badd-56a29c70880d | AM23: eu_eea_air_quality_ereporting
A24: ChinaHighAirPollutants (CHAP) | B24: Gold | C24: 91 | D24: environment | E24: degraded | F24: open | G24: grid_1km | H24: Needs raster support | I24: 3 | K24: Curated | L24: 2026 | M24: open | N24: 2026-10-22 | O24: pass | P24: pass | Q24: pass | R24: pass | S24: pass | T24: pass | U24: warn | V24: fail | W24: pass | X24: pass | Y24: pass | Z24: pass | AA24: pass | AB24: warn | AC24: pass | AD24: pass | AE24: pass | AF24: pass | AG24: warn | AH24: pass | AI24: n.a. | AJ24: n.a. | AK24: machine_metadata;format_match(warn);cadence(warn);join_key(warn) | AL24: https://weijing-rs.github.io/product.html | AM24: cn_wei_chap
A25: Daily Census Tract-Level PM2.5 Concentrations (2001-2005; 2006-2010; 2011-2015; 2016) | B25: Gold | C25: 92 | D25: environment | E25: healthy | F25: open | G25: tract | H25: Joins today | I25: 3 | J25: us_2014_2019_monthly_pm25_by_tract_cdc | K25: Curated | L25: 2015 | M25: open | N25: 2026-10-22 | O25: pass | P25: pass | Q25: pass | R25: pass | S25: pass | T25: pass | U25: warn | V25: pass | W25: warn | X25: pass | Y25: pass | Z25: pass | AA25: warn | AB25: not_checked | AC25: warn | AD25: pass | AE25: not_checked | AF25: pass | AG25: warn | AH25: warn | AI25: pass | AJ25: not_checked | AK25: format_match(warn);persistent_id(warn);recency(warn);version(warn);join_key(warn);format_gaia(warn) | AL25: https://catalog.data.gov/dataset/daily-census-tract-level-pm2-5-concentrations-2011-2015 | AM25: us_cdc_daily_tract_pm25
A26: ESA CCI Soil Moisture (active, passive, combined) v09.2 | B26: Gold | C26: 98 | D26: environment | E26: degraded | F26: attribution | G26: grid_0.25deg | H26: Needs raster support | I26: 3 | K26: Curated | L26: 2024 | M26: open | N26: 2026-10-22 | O26: pass | P26: pass | Q26: pass | R26: pass | S26: pass | T26: fail | U26: n.a. | V26: warn | W26: pass | X26: pass | Y26: pass | Z26: pass | AA26: pass | AB26: pass | AC26: pass | AD26: pass | AE26: pass | AF26: pass | AG26: pass | AH26: pass | AI26: n.a. | AJ26: n.a. | AK26: access_url;machine_metadata(warn) | AL26: https://climate.esa.int/en/projects/soil-moisture/ | AM26: global_esa_cci_soil_moisture
A27: ESA Climate Change Initiative Land Cover (CCI-LC) annual global maps 300 m, 1992-2020 (v2.0.7, v2.1.1) and C3S continuation | B27: Gold | C27: 98 | D27: environment | E27: degraded | F27: attribution | G27: grid_300m | H27: Needs raster support | I27: 3 | K27: Curated | L27: 2020 | M27: open | N27: 2026-10-22 | O27: pass | P27: pass | Q27: pass | R27: pass | S27: pass | T27: fail | U27: n.a. | V27: warn | W27: pass | X27: pass | Y27: pass | Z27: pass | AA27: pass | AB27: warn | AC27: pass | AD27: pass | AE27: pass | AF27: pass | AG27: pass | AH27: not_checked | AI27: n.a. | AJ27: n.a. | AK27: access_url;machine_metadata(warn);cadence(warn) | AL27: https://climate.esa.int/en/projects/land-cover/ | AM27: global_esa_cci_land_cover
A28: SatPM2.5 (Satellite-derived PM2.5) global estimates V6.GL.02.04 and V5.GL.05.02 | B28: Gold | C28: 95 | D28: environment | E28: degraded | F28: open | G28: grid_0.01deg | H28: Needs raster support | I28: 3 | K28: Curated | L28: 2023 | M28: open | N28: 2026-10-22 | O28: pass | P28: pass | Q28: pass | R28: pass | S28: pass | T28: pass | U28: warn | V28: fail | W28: pass | X28: pass | Y28: pass | Z28: pass | AA28: pass | AB28: warn | AC28: pass | AD28: pass | AE28: pass | AF28: pass | AG28: pass | AH28: pass | AI28: n.a. | AJ28: n.a. | AK28: machine_metadata;format_match(warn);cadence(warn) | AL28: https://sites.wustl.edu/acag/datasets/surface-pm2-5/ | AM28: global_acag_pm25
A29: Health facilities in Thailand 2020 | B29: Gold | C29: 100 | D29: health_outcome | E29: healthy | F29: attribution | G29: point | H29: Needs a count/distance step | I29: 3 | K29: Catalog lead | L29: 2020 | M29: open | N29: 2026-10-22 | O29: pass | P29: pass | Q29: pass | R29: pass | S29: pass | T29: pass | U29: pass | V29: pass | W29: warn | X29: fail | Y29: pass | Z29: pass | AA29: pass | AB29: not_checked | AC29: warn | AD29: pass | AE29: fail | AF29: pass | AG29: pass | AH29: pass | AI29: n.a. | AJ29: n.a. | AK29: archived;coverage;persistent_id(warn);version(warn) | AL29: https://data.opendevelopmentmekong.net/dataset/health-facilities-in-thailand-2020 | AM29: mekong_odm_health_facilities_in_thailand_2020
A30: U.S. Small-area Life Expectancy Estimates Project (USALEEP) | B30: Gold | C30: 94 | D30: health_outcome | E30: healthy | F30: open | G30: tract | H30: Joins today | I30: 3 | K30: Curated | L30: 2015 | M30: unknown | N30: 2026-10-22 | O30: pass | P30: pass | Q30: pass | R30: pass | S30: pass | T30: pass | U30: warn | V30: warn | W30: warn | X30: pass | Y30: pass | Z30: pass | AA30: warn | AB30: warn | AC30: warn | AD30: pass | AE30: warn | AF30: pass | AG30: pass | AH30: pass | AI30: n.a. | AJ30: n.a. | AK30: format_match(warn);machine_metadata(warn);persistent_id(warn);recency(warn);cadence(warn);version(warn);coverage(warn) | AL30: https://www.cdc.gov/nchs/nvss/usaleep/usaleep.html | AM30: us_cdc_usaleep
A31: Rural Urban Classification | B31: Gold | C31: 93 | D31: other | E31: healthy | F31: open | G31: output_area (OA; 188,880 OAs of c. 100-625 people) | H31: Joins today | I31: 2 | K31: Curated | L31: 2021 | M31: open | N31: 2026-10-22 | O31: pass | P31: pass | Q31: pass | R31: pass | S31: pass | T31: pass | U31: warn | V31: warn | W31: warn | X31: pass | Y31: pass | Z31: pass | AA31: pass | AB31: warn | AC31: pass | AD31: pass | AE31: fail | AF31: pass | AG31: warn | AH31: warn | AI31: n.a. | AJ31: n.a. | AK31: coverage;format_match(warn);machine_metadata(warn);persistent_id(warn);cadence(warn);join_key(warn);format_gaia(warn) | AL31: https://www.gov.uk/government/collections/rural-urban-classification | AM31: gb_defra_ons_rural_urban_classification
A32: Area Health Resources Files (AHRF) | B32: Gold | C32: 91 | D32: sdoh | E32: degraded | F32: open | G32: county | H32: Joins today | I32: 3 | K32: Curated | L32: 2025 | M32: open | N32: 2026-10-22 | O32: pass | P32: pass | Q32: pass | R32: pass | S32: pass | T32: pass | U32: warn | V32: fail | W32: warn | X32: pass | Y32: pass | Z32: pass | AA32: pass | AB32: pass | AC32: pass | AD32: pass | AE32: pass | AF32: pass | AG32: warn | AH32: pass | AI32: n.a. | AJ32: n.a. | AK32: machine_metadata;format_match(warn);persistent_id(warn);join_key(warn) | AL32: https://data.hrsa.gov/topics/health-workforce/ahrf | AM32: us_hrsa_ahrf
A33: Comprehensive Housing Affordability Strategy (CHAS) data | B33: Gold | C33: 92 | D33: sdoh | E33: healthy | F33: unknown | G33: block group (091), tract (080) | H33: Joins today | I33: 3 | K33: Curated | L33: 2022 | M33: open | N33: 2026-10-28 | O33: pass | P33: pass | Q33: pass | R33: pass | S33: pass | T33: pass | U33: pass | V33: not_checked | W33: not_checked | X33: pass | Y33: warn | Z33: pass | AA33: pass | AB33: not_checked | AC33: not_checked | AD33: pass | AE33: not_checked | AF33: pass | AG33: not_checked | AH33: pass | AI33: n.a. | AJ33: n.a. | AK33: license(warn) | AL33: https://www.huduser.gov/portal/datasets/cp.html | AM33: us_hud_chas
A34: NATA / AirToxScreen replication dataset 1996-2019 (tract and county risk tables) | B34: Gold | C34: 95 | D34: toxics | E34: healthy | F34: open | G34: tract | H34: Joins today | I34: 3 | K34: Curated | L34: 2020 | M34: open | N34: 2026-10-22 | O34: pass | P34: pass | Q34: pass | R34: pass | S34: pass | T34: pass | U34: n.a. | V34: pass | W34: pass | X34: fail | Y34: pass | Z34: pass | AA34: pass | AB34: warn | AC34: pass | AD34: pass | AE34: warn | AF34: pass | AG34: warn | AH34: warn | AI34: n.a. | AJ34: n.a. | AK34: archived;cadence(warn);coverage(warn);join_key(warn);format_gaia(warn) | AL34: https://zenodo-rdm.web.cern.ch/records/17187663 | AM34: us_zenodo_nata_replication_1996_2019
A35: 2021 Census Boundary Files | B35: Silver | C35: 93 | D35: boundaries | E35: healthy | F35: open | G35: block | H35: Joins today | I35: 1 | K35: Curated | L35: 2021 | M35: open | N35: 2026-10-28 | O35: pass | P35: pass | Q35: pass | R35: pass | S35: pass | T35: warn | U35: n.a. | V35: pass | W35: warn | X35: fail | Y35: pass | Z35: pass | AA35: pass | AB35: pass | AC35: warn | AD35: warn | AE35: warn | AF35: pass | AG35: pass | AH35: pass | AI35: n.a. | AJ35: n.a. | AK35: archived;access_url(warn);persistent_id(warn);version(warn);unit(warn);coverage(warn) | AL35: https://open.canada.ca/data/dataset/ef70dc3b-1069-4037-9bce-61f47e628a1d | AM35: ca_statcan_census_boundary_files_2021
A36: Australian Statistical Geography Standard (ASGS) Edition 3 digital boundary files | B36: Silver | C36: 91 | D36: boundaries | E36: healthy | F36: open | G36: block | H36: Joins today | I36: 1 | K36: Curated | L36: 2025 | M36: open | N36: 2026-10-28 | O36: pass | P36: pass | Q36: pass | R36: pass | S36: pass | T36: n.a. | U36: n.a. | V36: warn | W36: warn | X36: pass | Y36: pass | Z36: pass | AA36: pass | AB36: pass | AC36: pass | AD36: warn | AE36: pass | AF36: pass | AG36: pass | AH36: pass | AI36: n.a. | AJ36: n.a. | AK36: machine_metadata(warn);persistent_id(warn);unit(warn) | AL36: https://www.abs.gov.au/statistics/standards/australian-statistical-geography-standard-asgs-edition-3/jul2021-jun2026/access-and-downloads/digital-boundary-files | AM36: au_abs_asgs_boundaries
A37: Boundary-Line | B37: Silver | C37: 92 | D37: boundaries | E37: healthy | F37: unknown | G37: postcode_small_area | H37: Joins today | I37: 1 | K37: Curated | L37: 2026 | M37: open | N37: 2026-10-28 | O37: pass | P37: pass | Q37: pass | R37: pass | S37: pass | T37: pass | U37: warn | V37: warn | W37: warn | X37: pass | Y37: not_checked | Z37: warn | AA37: pass | AB37: pass | AC37: not_checked | AD37: not_checked | AE37: pass | AF37: pass | AG37: pass | AH37: pass | AI37: n.a. | AJ37: n.a. | AK37: format_match(warn);machine_metadata(warn);persistent_id(warn);temporal(warn) | AL37: https://www.ordnancesurvey.co.uk/products/boundary-line | AM37: gb_os_boundary_line
... A40: GeoNames geographical database | B40: Silver | C40: 92 | D40: boundaries | E40: degraded | F40: open | G40: point | H40: Needs a count/distance step | I40: 1 | K40: Curated | L40: 2026 | M40: open | N40: 2026-10-28 | O40: pass | P40: pass | Q40: pass | R40: pass | S40: pass | T40: pass | U40: pass | V40: fail | W40: warn | X40: pass | Y40: pass | Z40: warn | AA40: pass | AB40: pass | AC40: not_checked | AD40: pass | AE40: pass | AF40: pass | AG40: pass | AH40: pass | AI40: n.a. | AJ40: n.a. | AK40: machine_metadata;persistent_id(warn);temporal(warn) | AL40: https://www.geonames.org/export/ | AM40: global_geonames
A41: GeoNames postal codes | B41: Silver | C41: 95 | D41: boundaries | E41: degraded | F41: open | G41: point | H41: Needs a count/distance step | I41: 1 | K41: Curated | L41: current | M41: open | N41: 2026-10-28 | O41: pass | P41: pass | Q41: pass | R41: pass | S41: pass | T41: pass | U41: warn | V41: fail | W41: warn | X41: pass | Y41: pass | Z41: not_checked | AA41: not_checked | AB41: warn | AC41: not_checked | AD41: pass | AE41: pass | AF41: pass | AG41: pass | AH41: pass | AI41: n.a. | AJ41: n.a. | AK41: machine_metadata;format_match(warn);persistent_id(warn);cadence(warn) | AL41: https://www.geonames.org/export/ | AM41: global_geonames_postal_codes
A42: Local administrative units (LAU) - GISCO geodata | B42: Silver | C42: 84 | D42: boundaries | E42: healthy | F42: non-commercial | G42: admin3 | H42: Joins today | I42: 1 | K42: Curated | L42: 2024 | M42: open | N42: 2026-10-28 | O42: pass | P42: pass | Q42: pass | R42: pass | S42: pass | T42: pass | U42: warn | V42: warn | W42: warn | X42: pass | Y42: warn | Z42: pass | AA42: pass | AB42: pass | AC42: warn | AD42: warn | AE42: not_checked | AF42: pass | AG42: pass | AH42: pass | AI42: n.a. | AJ42: n.a. | AK42: format_match(warn);machine_metadata(warn);persistent_id(warn);license(warn);version(warn);unit(warn) | AL42: https://ec.europa.eu/eurostat/web/gisco/geodata/statistical-units/local-administrative-units | AM42: eu_eurostat_gisco_lau
...

Sheet Refined set
A1: Dataset | B1: Publisher | C1: Theme | D1: Coverage | E1: Finest unit | F1: Years | G1: Latest year | H1: License class | I1: Licence (confirmed) | J1: Access | K1: Format | L1: Gaia fit | M1: Health relevance (0-3) | N1: In gaiaCatalog | O1: Tier | P1: Score | Q1: Landing page | R1: id
A2: 2022 Social Vulnerability by US Census Block Group | B2: Harvard Dataverse deposit (derived from CDC/ATSDR SVI) | D2: US | E2: block_group | F2: title says 2022; file name says 2020; not reconciled | G2: 2022 | H2: open | I2: CC0 1.0 | J2: open_download | K2: tab | O2: Silver | Q2: https://doi.org/10.7910/dvn/arbhpk | R2: us_harvard_svi_percentiles_block_group
A3: Beachwatch swim sites with pollution forecasts and latest water quality, New South Wales | B3: NSW Beachwatch (published via publicdata.au / Zenodo) | D3: NSW swim sites (246 rows) | E3: point | F3: live feed, version 2026-10-29 | G3: 2026 | H3: open | I3: CC BY 4.0 | J3: open_download | K3: csv; parquet; json; xlsx | O3: Gold | Q3: https://doi.org/10.5281/zenodo.23113632 | R3: au_nsw_beachwatch_swim_sites_live
A4: Birthing Friendly Hospitals with Geocoded Addresses | B4: CMS Provider Data Catalog | E4: facility (point; geocoded) | F4: current snapshot; catalog 'modified' 2026-10-22, next update 2027-01-20 | H4: public_domain_us_federal | I4: not stated in catalog metadata (federal open data; unverified) | J4: open_download (CSV via DKAN API) | O4: Silver | Q4: https://data.cms.gov/provider-data/dataset/hbf-map | R4: us_cms_pdc_hbf_map
A5: Buprenorphine Prescribing Requirements and Limitations | B5: Center for Public Health Law Research (Temple University; LawAtlas) | D5: US (50 states + DC) | E5: state | F5: 2023-03-01 to 2024-09-01 | G5: 2024 | J5: registration | K5: not stated | O5: Silver | Q5: https://doi.org/10.60541/snt6-m904 | R5: us_lawatlas_buprenorphine_prescribing_laws
A6: Calculating Hazard Indices for PFAS in California's Drinking Water | B6: Mendeley Data (Geotracker-derived) | D6: California (Geotracker monitoring locations) | E6: point | F6: years not stated (published 2024-11-22) | H6: open | I6: CC BY 4.0 | J6: open_download ("Download All") | K6: xlsx | O6: Silver | Q6: https://doi.org/10.17632/hy28gb37tg | R6: us_mendeley_california_pfas_hazard_indices
A7: Compilation of riverine water quality data from the Great Barrier Reef catchment area, northeastern Australia: version 2.0 | B7: James Cook University (Great Barrier Reef catchments) | D7: Great Barrier Reef catchment (466 sites) | E7: point | F7: 1986-10-19 to 2023-02-08 | G7: 2023 | H7: open | I7: CC BY 4.0 (page: "will be licensed under") | J7: open_download ("Open: free access under license") | K7: xlsx; zip | O7: Silver | Q7: https://doi.org/10.25903/pase-na93 | R7: au_jcu_gbr_catchment_riverine_water_quality_v2
A8: Complications and Unplanned Hospital Visits - PPS-Exempt Cancer Hospital | B8: CMS Provider Data Catalog | E8: facility (11 PPS-exempt cancer hospitals) | F8: current snapshot; catalog 'modified' 2026-10-22, next update 2027-01-20 | H8: public_domain_us_federal | I8: not stated in catalog metadata (federal open data; unverified) | J8: open_download (CSV via DKAN API) | O8: Silver | Q8: https://data.cms.gov/provider-data/dataset/z8ax-x9j1 | R8: us_cms_pdc_z8ax_x9j1
A9: COVID-19 US State Policy Database | B9: Boston University School of Public Health (CUSP; hosted on openICPSR) | D9: US (50 states + DC) | E9: state | F9: 2/2020 to 6/2020 (time period); version V143 dated 2022-03-30 | G9: 2020 | J9: open_download (assumed: no login named) | K9: not stated (folder "COVID-19-US-State-Policy-Database-master"; data sources on a linked page) | O9: Silver | Q9: https://doi.org/10.3886/e119446 | R9: us_cusp_covid19_state_policy_database
A10: COVID-19: State Emergency Declarations & Mitigation Policies | B10: Center for Public Health Law Research (Temple University; LawAtlas) | D10: US (50 states + DC) | E10: state | F10: 2020-01-20 to 2020-07-01 | G10: 2020 | J10: registration | K10: not stated | O10: Silver | Q10: https://doi.org/10.60541/ethb-2t35 | R10: us_lawatlas_covid19_state_emergency_declarations
A11: Cyanobacterial HAB Monitoring using Satellite Imagery for the United States Great Lakes region created by the NOAA Harmful Algal Bloom Forecasting Branch (HAB-F) from 2000 to 2024 (NCEI Accession 0312614) | B11: NOAA NCEI | D11: US Great Lakes (Erie, Sandusky Bay, Saginaw Bay, Green Bay, Winnebago) | E11: raster | F11: 2000-06-01 to 2024-11-15 (July-October blooms) | G11: 2024 | H11: open | I11: CC0 1.0 Universal | J11: open_download (HTTPS) | K11: csv; geotiff | O11: Silver | Q11: https://doi.org/10.25921/wzk1-r208 | R11: us_noaa_ncei_greatlakes_cyano_hab_satellite
A12: Data and Materials for: Statewide Intensification of Harmful Algal Blooms Across California Lakes and Reservoirs | B12: Mendeley Data (paper supplement) | D12: California lakes and reservoirs | F12: years not stated (published 2026-03-16) | H12: open | I12: CC BY 4.0 | J12: open_download ("Download All") | K12: not listed on page (shapefiles in description) | O12: Silver | Q12: https://doi.org/10.17632/66dm3vs3g2 | R12: us_mendeley_california_lakes_hab_intensification
A13: Daytime surface urban heat island intensity across 6022 global cities in summer 2019 | B13: Zenodo deposit | D13: 6,022 cities worldwide | E13: point | F13: summer 2019 (single season) | G13: 2019 | H13: open | I13: CC BY 4.0 | J13: open_download | K13: xlsx with coordinates | O13: Gold | Q13: https://doi.org/10.5281/zenodo.17644686 | R13: global_zenodo_daytime_suhi_6022_cities_2019
A14: Electronic Cigarette Laws | B14: Center for Public Health Law Research (Temple University; LawAtlas) | D14: US (50 states + DC) | E14: state | F14: 2016-08-01 to 2017-08-01 | G14: 2017 | J14: registration | K14: not stated | O14: Silver | Q14: https://doi.org/10.60541/rq4m-pk67 | R14: us_lawatlas_e_cigarette_laws
A15: ERA5-Land weekly: Air temperature at 2 meter above surface, weekly time series for Europe at 1 km resolution (2016 - 2020) | B15: Zenodo deposit (OpenGeoHub) | D15: Europe (EPSG:3035) | E15: grid_1km | F15: 2016-01-01 to 2020-12-31, weekly | G15: 2020 | H15: open | I15: CC BY-SA 4.0 | J15: open_download | K15: geotiff | O15: Gold | Q15: https://doi.org/10.5281/zenodo.6559121 | R15: eu_zenodo_era5land_weekly_air_temperature_1km
A16: Experimental Harmful Algal Bloom (HAB) bulletin forecast products and associated satellite imagery from Lake Erie from 2008-09-04 to 2016-11-01 created by the NOAA National Centers for Coastal Ocean Science | B16: NOAA NCEI / NOS | D16: Lake Erie | E16: raster | F16: 2008-09-04 to 2016-11-01 | G16: 2016 | H16: open | I16: public domain (US Government work, 17 U.S.C. 105; federal rule applied) | J16: open_download (OneStop / NCEI browse; other options by contacting NCEI) | K16: geotiff; pdf | O16: Silver | Q16: https://doi.org/10.25921/q053-h813 | R16: us_noaa_ncei_lake_erie_hab_bulletin_experimental
A17: Global 0.05° daily mean land surface temperature product (2001-2023) | B17: Zenodo deposit | D17: global | E17: grid_0.05deg | F17: 2001-2023 in this record (1981-2000 is a separate record) | G17: 2023 | H17: open | I17: CC BY 4.0 | J17: open_download (per-year RAR archives, 29.3 GB) | K17: RAR archives; inner format not stated | O17: Gold | Q17: https://doi.org/10.5281/zenodo.15187724 | R17: global_zenodo_lst_005deg_daily_2001_2023
A18: Global Gridded Relative Deprivation Index (GRDI), Version 1 | B18: NASA SEDAC (CIESIN, Columbia University) | D18: global (30 arc-second pixels) | E18: grid_1km | F18: 2010-2020 | G18: 2020 | H18: open | I18: CC BY 4.0 | J18: open_download | K18: geotiff (zip) | O18: Gold | Q18: https://doi.org/10.7910/dvn/vosv99 | R18: global_ciesin_grdi_v1
A19: Global High Resolution Daily Urban Extreme Heat Exposure (UHE-Daily), 1983 - 2016 | B19: NASA SEDAC (CIESIN, Columbia University) | D19: global (>10,000 urban settlements) | E19: polygon | F19: 1983-01-01 to 2016-12-31, daily | G19: 2016 | H19: open | I19: "openly shared, without restriction" (EOSDIS Data Use and Citation Guidance) | J19: open_download (login not stated) | K19: shp; csv | O19: Silver | Q19: https://doi.org/10.7927/fq7g-ny13 | R19: global_sedac_uhe_daily_1983_2016
A20: Global Subnational Atlas of Poverty | B20: World Bank-derived panel (Harvard Dataverse deposit) | D20: global | E20: admin1 | F20: panel poverty rates; "version August 2022"; years not in the record metadata | H20: open | I20: CC0 1.0 | J20: open_download | K20: xlsx | O20: Silver | Q20: https://doi.org/10.7910/dvn/mlhfaf | R20: global_harvard_gsap_poverty_panel
A21: Good Samaritan Overdose Prevention Laws | B21: PDAPS | E21: state (50 states + DC code; no local) | F21: 2007-2023; effective dates: yes: per-state 'effective' and 'through' dates | I21: not stated on page; full pin citations behind paid subscription ($29/month) | J21: free account (web view); download not tested | O21: Silver | Q21: https://pdaps.org/datasets/good-samaritan-overdose-laws-1501695153 | R21: us_pdaps_good_samaritan_overdose_laws_1501695153
A22: GridEX: A Dataset for Assessing the Area-wide Extreme Heat and Cold (EHE/ECE) Exposure in the United States: 2008-2022 | B22: Harvard Dataverse deposit (GridEX; derived from NOAA ISD) | D22: United States | E22: tract | F22: 2008-2022 | G22: 2022 | H22: open | I22: CC0 1.0 | J22: open_download | K22: csv; rds; geotiff | O22: Gold | Q22: https://doi.org/10.7910/dvn/djgkdj | R22: us_gridex_extreme_heat_cold_events
A23: HadISDH.extremes: gridded global monthly land surface wet bulb and dry bulb temperature extremes index data version 1.0.0.2022f | B23: Met Office Hadley Centre / CEDA | D23: near-global land surface | E23: grid_5deg | F23: 1973-2022, monthly | G23: 2022 | H23: open | I23: Open Government Licence v3.0 | J23: open_download (web download; OPeNDAP) | K23: netcdf | O23: Silver | Q23: https://doi.org/10.5285/2d1613955e1b4cd1b156e5f3edbd7e66 | R23: gb_ceda_hadisdh_extremes
A24: Health Impact Assessment (HIA) Bills | B24: LawAtlas | E24: state (+DC/territories; 51 jurisdictions) | F24: 2012-01-01 to 2016-12-31; effective dates: yes: Valid From / Updated Through on page; per-law effective dates in the download (not checked) | I24: not stated on page; 'Data Licensing' link target 404 under /data-licensing | J24: free account required to download data/codebook | O24: Silver | Q24: https://lawatlas.org/datasets/hia-bills | R24: us_lawatlas_hia_bills
A25: Home Health Care - Zip Codes | B25: CMS Provider Data Catalog | E25: ZIP (agency service areas) | F25: current snapshot; catalog 'modified' 2026-10-22, next update 2027-01-20 | H25: public_domain_us_federal | I25: not stated in catalog metadata (federal open data; unverified) | J25: open_download (CSV via DKAN API) | O25: Silver | Q25: https://data.cms.gov/provider-data/dataset/m5eg-upu5 | R25: us_cms_pdc_m5eg_upu5
A26: Hospice - Zip Data | B26: CMS Provider Data Catalog | E26: ZIP (hospice service ZIPs) | F26: current snapshot; catalog 'modified' 2026-10-22, next update 2027-01-20 | H26: public_domain_us_federal | I26: not stated in catalog metadata (federal open data; unverified) | J26: open_download (CSV via DKAN API) | O26: Silver | Q26: https://data.cms.gov/provider-data/dataset/95rg-2usp | R26: us_cms_pdc_95rg_2usp
A27: Inpatient Rehabilitation Facility - General Information | B27: CMS Provider Data Catalog | E27: facility (address, ZIP) | F27: current snapshot; catalog 'modified' 2026-10-22, next update 2027-01-20 | H27: public_domain_us_federal | I27: not stated in catalog metadata (federal open data; unverified) | J27: open_download (CSV via DKAN API) | O27: Silver | Q27: https://data.cms.gov/provider-data/dataset/7t8x-u3ir | R27: us_cms_pdc_7t8x_u3ir
A28: Legal Landscape of Gabapentin Drug Scheduling and Required Prescription Drug Monitoring | B28: Center for Public Health Law Research (Temple University; LawAtlas) | D28: US (50 states + DC) | E28: state | F28: 2016-01-01 to 2024-12-31 | G28: 2024 | J28: registration | K28: not stated | O28: Silver | Q28: https://doi.org/10.60541/fe0h-sx30 | R28: us_lawatlas_gabapentin_scheduling_pdmp_laws
A29: Local Eviction Laws | B29: LawAtlas | E29: city (30 cities) | F29: 2021-01-01 (single date); effective dates: yes: Valid From / Updated Through on page; per-law effective dates in the download (not checked) | I29: not stated on page; 'Data Licensing' link target 404 under /data-licensing | J29: free account required to download data/codebook | O29: Silver | Q29: https://lawatlas.org/datasets/local-eviction-laws | R29: us_lawatlas_local_eviction_laws
A30: Long-Term Care Hospital - General Information | B30: CMS Provider Data Catalog | E30: facility (address, ZIP) | F30: current snapshot; catalog 'modified' 2026-10-22, next update 2027-01-20 | H30: public_domain_us_federal | I30: not stated in catalog metadata (federal open data; unverified) | J30: open_download (CSV via DKAN API) | O30: Silver | Q30: https://data.cms.gov/provider-data/dataset/azum-44iv | R30: us_cms_pdc_azum_44iv
A31: MODIS/Terra Land Surface Temperature/Emissivity Daily L3 Global 1km SIN Grid V061 | B31: NASA LP DAAC | D31: global (sinusoidal tiles) | E31: raster | F31: 2000-02-24 to present, daily | G31: 2026 | H31: open | I31: "openly shared, without restriction" (EOSDIS Data Use and Citation Guidance) | J31: open_download (login not stated; cloud-enabled) | K31: HDF-EOS2 (.hdf) | O31: Silver | Q31: https://doi.org/10.5067/modis/mod11a1.061 | R31: global_nasa_mod11a1_v061
A32: Naloxone Overdose Prevention Laws | B32: PDAPS | E32: state (50 states + DC code; no local) | F32: 2001-2022; effective dates: yes: per-state 'effective' and 'through' dates | I32: not stated on page; full pin citations behind paid subscription ($29/month) | J32: free account (web view); download not tested | O32: Silver | Q32: https://pdaps.org/datasets/laws-regulating-administration-of-naloxone-1501695139 | R32: us_pdaps_laws_regulating_administration_of_naloxone_1501695
A33: National Multidimensional Poverty Index | B33: NITI Aayog (via Climateverse India) | D33: India (state and district) | E33: admin2 | F33: 2015-2023 | G33: 2023 | H33: open | I33: CC0 1.0 | J33: record lists only codebook.json/codebook.md; data files not listed | K33: codebook only (json; md) | O33: Silver | Q33: https://doi.org/10.71646/ljsccn | R33: in_climateverse_national_mpi_state_district
A34: National Poverty Line - Subnational Poverty | B34: The World Bank | D34: world (national poverty lines) | E34: admin1 | F34: 1992-2016, annual | G34: 2016 | H34: open | I34: CC BY 4.0 | J34: open_download (via Databank; CSV/Excel zip) | K34: csv; xlsx (zip) | O34: Gold | Q34: https://doi.org/10.57966/tk74-ep75 | R34: global_worldbank_national_poverty_line_subnational
A35: Neighborhood Deprivation Index for year 2010, using the 2010 census geographic boundaries | B35: CEHI Data Hub | D35: USA (all states) | E35: tract | F35: 2010 (single year) | G35: 2010 | J35: "Access Restriction: Not available"; login not stated | K35: csv | O35: Silver | Q35: https://doi.org/10.25614/ndi_2010_trt_allstates | R35: us_cehi_ndi_2010_tract
A36: NOAA nClimGrid-Daily Version 1 – Daily gridded temperature and precipitation for the Contiguous United States since 1951 | B36: NOAA NCEI | D36: contiguous US | E36: grid_5km | F36: 1951-01-01 to present, daily | G36: 2026 | H36: open | I36: public domain (US Government work, 17 U.S.C. 105; federal rule applied) | J36: open_download (direct, THREDDS, AWS S3) | K36: netcdf; csv | O36: Gold | Q36: https://doi.org/10.25921/c4gt-r169 | R36: us_noaa_nclimgrid_daily
A37: Poverty Mapping Project: Global Subnational Infant Mortality Rates | B37: CIESIN (Columbia University), Poverty Mapping Project | D37: global (country list in record) | E37: polygon | F37: 2000 (single year) | G37: 2000 | H37: open | I37: CC BY 4.0 | J37: open_download | K37: shp; grid; xls; tabular zip | O37: Silver | Q37: https://doi.org/10.7910/dvn/wtnahq | R37: global_ciesin_povmap_subnational_infant_mortality
A38: Poverty Mapping Project: Global Subnational Prevalence of Child Malnutrition | B38: CIESIN (Columbia University), Poverty Mapping Project | D38: global (country list in record) | E38: polygon | F38: 1990-2002 (most recent subnational year per country) | G38: 2002 | H38: open | I38: CC BY 4.0 | J38: open_download | K38: shp; grid; tabular zip | O38: Silver | Q38: https://doi.org/10.7910/dvn/0ljjoj | R38: global_ciesin_povmap_subnational_child_malnutrition
A39: Poverty Mapping Project: Small Area Estimates of Poverty and Inequality | B39: CIESIN (Columbia University), Poverty Mapping Project | D39: about twenty countries (record text) | E39: polygon | F39: 1990-2002 | G39: 2002 | H39: open | I39: CC BY 4.0 | J39: open_download | K39: shp; csv/tabular zip; centroid zip | O39: Silver | Q39: https://doi.org/10.7910/dvn/rkrw8q | R39: global_ciesin_povmap_small_area_poverty_inequality
A40: Prescription Drug Monitoring Program Laws: Reporting, Mandates & Access | B40: LawAtlas | E40: state (+DC/territories; 51 jurisdictions) | F40: 2014-01-01 to 2023-12-31; effective dates: yes: Valid From / Updated Through on page; per-law effective dates in the download (not checked) | I40: not stated on page; 'Data Licensing' link target 404 under /data-licensing | J40: free account required to download data/codebook | O40: Silver | Q40: https://lawatlas.org/datasets/prescription-drug-monitoring-program-laws-reporting-mandates-access-2014-2023 | R40: us_lawatlas_prescription_drug_monitoring_program_laws_reportin
...

Sheet Browser queue
A1: Domain | B1: Dataset | C1: Reason | D1: What to confirm | E1: Shortlist | F1: Landing page | G1: Archive copy | H1: id
